Workbook

Sheet 說明
A1: 澳洲可出租資料中心盤點
A2: 資料日期：2026-10-03 ｜ 收錄門檻：5 MW 以上 ｜ 範圍：澳洲 8 個州與領地的可出租資料中心
A4: 盤點範圍
A5: 收錄條件 | B5: 同時符合：(1) 可由第三方承租（託管、批發型、建置型／powered shell）；(2) 專案或獨立分期容量 5 MW 以上（未公布 MW 但明顯為大型園區者亦收錄，容量欄顯示「未公布」）；(3) 狀態為施工中、已核准尚未動工、已送件審查中，或近期完工／已營運但仍有 5 MW 以上可租容量或擴建。
A6: 不收錄 | B6: 雲端巨頭自建或終端使用者自用（Amazon/AWS、Microsoft、Google、Meta、Oracle 等）、不足 5 MW、已撤案或遭否決者，列於「排除清單」僅供稽核。已預租給特定雲端業者或 AI 公司的第三方專案不屬於自建，仍收錄並在「已知租戶」註明。
A7: 資料日期 | B7: 2026-10-03。狀態與完工時間以此日期可取得的公開資訊為準。
A8: 涵蓋地區 | B8: 新南威爾斯州、維多利亞州、昆士蘭州、西澳州、南澳州、首都領地、塔斯馬尼亞州、北領地；零筆的州仍有獨立工作表，列出查過的來源。
A10: 工作表導覽（點選名稱可跳轉）
A11: 總覽 | B11: 關鍵指標、各州 × 狀態、各州 × 完工時間窗、各州容量（只計主清單），另有觀察名單統計與重點發現；統計皆為引用「專案清單」的即時公式。
A12: 專案清單 | B12: 全部收錄專案的完整欄位，依完工時間窗 → 狀態 → 容量排序；可用表頭箭頭篩選。
A13: 各州工作表 | B13: 每州一張精簡表：NSW 新南威爾斯、VIC 維多利亞、QLD 昆士蘭、WA 西澳、SA 南澳、ACT 首都領地、TAS 塔斯馬尼亞、NT 北領地。零筆的州列出搜尋紀錄、資料缺口與代理備註。
A14: 完工時間窗 | B14: 依可用時間分組，附各組已知 MW 小計。
A15: 差異與待確認 | B15: 跨來源差異、專案層級差異與低可信度專案，決策前請先看。
A16: 排除清單 | B16: 不符收錄條件的項目與原因，僅供稽核。
A17: 來源 | B17: 所有引用網址，分類為政府／營運商／媒體／其他，並列出引用的專案。
A18: 搜尋紀錄 | B18: 各州、各代理的搜尋紀錄、資料缺口與備註。
A20: 狀態定義（狀態欄的顏色）
A21: 施工中 | B21: 已有具日期的動工證據：開工通知、施工環境管理計畫（CEMP）核准、營運商新聞稿、封頂等。
A22: 已核准、尚未動工 | B22: 已取得規劃許可或開發許可，尚無施工證據。
A23: 近期完工（仍有容量） | B23: 2025-07 以後通電或啟用，且仍有 5 MW 以上未出租或擴建容量。
A24: 已營運（有餘裕／擴建） | B24: 已營運的可租設施，有可信公開證據顯示 5 MW 以上未出租容量，或正進行 5 MW 以上擴建。
A25: 已送件、審查中 | B25: 已公開宣布並正式向規劃主管機關送件（SEARs、EIS、DA、許可申請），尚未核准；僅有傳聞而未送件者不收錄。
A27: 完工時間窗
A28: 已可用／營運中 | B28: 已營運或已交付。
A29: 2026 Q4 – 2027 Q2 | B29: 預計 2026 年 10 月至 2027 年 6 月完工或啟用。
A30: 2027 下半年 | B30: 預計 2027 年 7 月至 12 月。
A31: 2028 年以後 | B31: 預計 2028 年或更晚。
A32: 完工日未公布 | B32: 尚無可靠來源公布完工日期。
A33: 判定方式 | B33: 由彙整程式依「預計完工（原文）」與狀態推得；每個專案的判定依據列在「完工時間窗」工作表的「時間窗依據」欄，並附在「專案清單」完工時間窗欄的儲存格註解。FY 為澳洲會計年度（7 月 1 日起算），例如 FY27 = 2026-07 至 2027-06。
A35: 可租判斷
A36: 可租 | B36: 營運商明確以託管或批發方式對第三方出租。
A37: 大概可租 | B37: 開發商或營運商的模式通常對外出租，但尚未公布租戶或出租條件。
A38: 待確認 | B38: 出租模式不明或可能為單一客戶專用，需向營運商確認。
A40: 分級：主清單與觀察名單
A41: 主清單 | B41: 可租判斷為「可租」或「大概可租」的專案。總覽的主要統計、各組小計與各州摘要的主數字只計主清單。
A42: 觀察名單 (出租性待確認) | B42: 可租判斷為「待確認」的專案，例如出售 GPU 算力而非出租機房空間的垂直整合 AI 雲業者、尚未核准且仍在等待主力客戶的專案、首期可用容量不足 5 MW 的場址，或由彙整者另行判定者。不計入主要統計，但保留顯示，讓每州都看得到現有專案；原因見「分級說明」欄。
A44: 可信度（字色）
A45: 高 | B45: 已開啟並閱讀具日期的政府或營運商一手來源。
A46: 中 | B46: 有可信的產業媒體報導，或有一手來源但未開啟原文。
A47: 低 | B47: 僅有聚合網站或搜尋摘要，需再查證才能作為依據。
...

Sheet 總覽
A1: 澳洲可出租資料中心盤點：總覽
A2: 資料日期：2026-10-03 ｜ 主要統計只計主清單，觀察名單另列 ｜ 數字皆為引用「專案清單」的即時公式
A4: 可租、5 MW 以上、而且真的在蓋的專案只有 15 筆；落在 2026 Q4 – 2027 Q2 交付的只有 5 筆，且多半已預售或尚待營運商確認。
A5: 本次盤點由 18 個搜索代理分州地毯式搜索（NSW、VIC 各 3 個角度，其餘各州各 2 個），再由我對關鍵項目回頭讀政府文件與營運商原文做獨立驗證。結果共 79 筆：主清單 60 筆（可租或大概可租）、觀察名單 19 筆（出租性待確認）；另有 190 筆經查證後排除，其中雲端巨頭自建 21 筆、不足 5 MW 的 45 筆、已撤案 9 筆。每一筆都附地址與地圖座標：72 筆有完整門牌，其餘 7 筆只到街道、郊區或區域（例如 Minchinbury、Mawson Lakes、Project Ares），地圖上以虛線外框標示為近似。
A6: 主清單 60 筆裡，施工中 15 筆、已核准尚未動工 16 筆、已正式送件審查中 26 筆、已營運或近期完工 3 筆。落在你要的 2026 Q4 – 2027 Q2 時間窗的有 5 筆：GreenSquareDC SYD1 第一期（雪梨 Norwest，約 15 MW）、STACK MEL01C/D（墨爾本 Truganina，各 54 MW）、STACK MEL02（252 MW）、Vantage MEL1（Tullamarine，64 MW）、CDC Maddington 第一棟（Perth，約 34 MW，2027 年 1 月）。另外 Macquarie IC3 Super West 首期 6 MW 和 Cloud Carrier 的 Southern Highlands DB1（28 MW 裸殼）已經可用。
A7: 真正的限制不在『有沒有在蓋』，而在『有沒有剩』。NEXTDC 自己的 FY26 簡報顯示，NSW／ACT 的已簽約容量是已建成容量的 306%、VIC 是 261%；CDC 的容量多為長約預簽，主要服務政府與關鍵基礎設施客戶。公開資料看不到任何一棟的未租區塊，必須直接向營運商詢問。
A8: 各州概況：NSW（主清單 33 筆）與 VIC（21 筆）佔絕大多數；QLD、WA、ACT 各 2 筆；SA、TAS、NT 沒有已確認可租的專案，只有觀察名單（DigiCo 阿德雷德、DCI ADL03、IREN Bundey、Firmus 塔斯馬尼亞三案、Energy North 的 Project Ares），它們不是出租機房空間，或尚無核准與客戶。
A10: 關鍵指標（只計主清單）
B11: 主清單專案（件） | C11: 已知容量合計（MW） | D11: 容量未公布（件） | E11: 可信度「高」（件） | F11: 施工中（件） | G11: 2027 Q2 前可用（件） | H11: 另有觀察名單（件）
B12: =COUNTIFS(專案清單!$R$2:$R$80,"主清單") -> 60 | C12: =SUMIFS(專案清單!$M$2:$M$80,專案清單!$R$2:$R$80,"主清單") -> 14195.6 | D12: =COUNTIFS(專案清單!$M$2:$M$80,"未公布",專案清單!$R$2:$R$80,"主清單") -> 4 | E12: =COUNTIFS(專案清單!$AD$2:$AD$80,"高",專案清單!$R$2:$R$80,"主清單") -> 46 | F12: =COUNTIFS(專案清單!$Q$2:$Q$80,"施工中",專案清單!$R$2:$R$80,"主清單") -> 15 | G12: =COUNTIFS(專案清單!$X$2:$X$80,"已可用／營運中",專案清單!$R$2:$R$80,"主清單")+COUNTIFS(專案清單!$X$2:$X$80,"2026 Q4 – 2027 Q2",專案清單!$R$2:$R$80,"主清單") -> 8 | H12: =COUNTIFS(專案清單!$R$2:$R$80,"觀察名單 (出租性待確認)") -> 19
B13: ="另有排除項目 "&COUNTA(排除清單!$A$5:$A$194)&" 件（僅供稽核，見「排除清單」）" -> 另有排除項目 190 件（僅供稽核，見「排除清單」）
A15: 各州 × 狀態（主清單件數）
A16: 州 | B16: 州名 | C16: 施工中 | D16: 已核准、尚未動工 | E16: 近期完工（仍有容量） | F16: 已營運（有餘裕／擴建） | G16: 已送件、審查中 | H16: 合計
A17: NSW | B17: 新南威爾斯州 | C17: =COUNTIFS(專案清單!$B$2:$B$80,$B17,專案清單!$Q$2:$Q$80,C$16,專案清單!$R$2:$R$80,"主清單") -> 6 | D17: =COUNTIFS(專案清單!$B$2:$B$80,$B17,專案清單!$Q$2:$Q$80,D$16,專案清單!$R$2:$R$80,"主清單") -> 10 | E17: =COUNTIFS(專案清單!$B$2:$B$80,$B17,專案清單!$Q$2:$Q$80,E$16,專案清單!$R$2:$R$80,"主清單") -> 1 | F17: =COUNTIFS(專案清單!$B$2:$B$80,$B17,專案清單!$Q$2:$Q$80,F$16,專案清單!$R$2:$R$80,"主清單") -> 2 | G17: =COUNTIFS(專案清單!$B$2:$B$80,$B17,專案清單!$Q$2:$Q$80,G$16,專案清單!$R$2:$R$80,"主清單") -> 14 | H17: =SUM(C17:G17) -> 33
A18: VIC | B18: 維多利亞州 | C18: =COUNTIFS(專案清單!$B$2:$B$80,$B18,專案清單!$Q$2:$Q$80,C$16,專案清單!$R$2:$R$80,"主清單") -> 7 | D18: =COUNTIFS(專案清單!$B$2:$B$80,$B18,專案清單!$Q$2:$Q$80,D$16,專案清單!$R$2:$R$80,"主清單") -> 4 | E18: =COUNTIFS(專案清單!$B$2:$B$80,$B18,專案清單!$Q$2:$Q$80,E$16,專案清單!$R$2:$R$80,"主清單") -> 0 | F18: =COUNTIFS(專案清單!$B$2:$B$80,$B18,專案清單!$Q$2:$Q$80,F$16,專案清單!$R$2:$R$80,"主清單") -> 0 | G18: =COUNTIFS(專案清單!$B$2:$B$80,$B18,專案清單!$Q$2:$Q$80,G$16,專案清單!$R$2:$R$80,"主清單") -> 10 | H18: =SUM(C18:G18) -> 21
A19: QLD | B19: 昆士蘭州 | C19: =COUNTIFS(專案清單!$B$2:$B$80,$B19,專案清單!$Q$2:$Q$80,C$16,專案清單!$R$2:$R$80,"主清單") -> 0 | D19: =COUNTIFS(專案清單!$B$2:$B$80,$B19,專案清單!$Q$2:$Q$80,D$16,專案清單!$R$2:$R$80,"主清單") -> 1 | E19: =COUNTIFS(專案清單!$B$2:$B$80,$B19,專案清單!$Q$2:$Q$80,E$16,專案清單!$R$2:$R$80,"主清單") -> 0 | F19: =COUNTIFS(專案清單!$B$2:$B$80,$B19,專案清單!$Q$2:$Q$80,F$16,專案清單!$R$2:$R$80,"主清單") -> 0 | G19: =COUNTIFS(專案清單!$B$2:$B$80,$B19,專案清單!$Q$2:$Q$80,G$16,專案清單!$R$2:$R$80,"主清單") -> 1 | H19: =SUM(C19:G19) -> 2
A20: WA | B20: 西澳州 | C20: =COUNTIFS(專案清單!$B$2:$B$80,$B20,專案清單!$Q$2:$Q$80,C$16,專案清單!$R$2:$R$80,"主清單") -> 1 | D20: =COUNTIFS(專案清單!$B$2:$B$80,$B20,專案清單!$Q$2:$Q$80,D$16,專案清單!$R$2:$R$80,"主清單") -> 0 | E20: =COUNTIFS(專案清單!$B$2:$B$80,$B20,專案清單!$Q$2:$Q$80,E$16,專案清單!$R$2:$R$80,"主清單") -> 0 | F20: =COUNTIFS(專案清單!$B$2:$B$80,$B20,專案清單!$Q$2:$Q$80,F$16,專案清單!$R$2:$R$80,"主清單") -> 0 | G20: =COUNTIFS(專案清單!$B$2:$B$80,$B20,專案清單!$Q$2:$Q$80,G$16,專案清單!$R$2:$R$80,"主清單") -> 1 | H20: =SUM(C20:G20) -> 2
A21: SA | B21: 南澳州 | C21: =COUNTIFS(專案清單!$B$2:$B$80,$B21,專案清單!$Q$2:$Q$80,C$16,專案清單!$R$2:$R$80,"主清單") -> 0 | D21: =COUNTIFS(專案清單!$B$2:$B$80,$B21,專案清單!$Q$2:$Q$80,D$16,專案清單!$R$2:$R$80,"主清單") -> 0 | E21: =COUNTIFS(專案清單!$B$2:$B$80,$B21,專案清單!$Q$2:$Q$80,E$16,專案清單!$R$2:$R$80,"主清單") -> 0 | F21: =COUNTIFS(專案清單!$B$2:$B$80,$B21,專案清單!$Q$2:$Q$80,F$16,專案清單!$R$2:$R$80,"主清單") -> 0 | G21: =COUNTIFS(專案清單!$B$2:$B$80,$B21,專案清單!$Q$2:$Q$80,G$16,專案清單!$R$2:$R$80,"主清單") -> 0 | H21: =SUM(C21:G21) -> 0
A22: ACT | B22: 首都領地 | C22: =COUNTIFS(專案清單!$B$2:$B$80,$B22,專案清單!$Q$2:$Q$80,C$16,專案清單!$R$2:$R$80,"主清單") -> 1 | D22: =COUNTIFS(專案清單!$B$2:$B$80,$B22,專案清單!$Q$2:$Q$80,D$16,專案清單!$R$2:$R$80,"主清單") -> 1 | E22: =COUNTIFS(專案清單!$B$2:$B$80,$B22,專案清單!$Q$2:$Q$80,E$16,專案清單!$R$2:$R$80,"主清單") -> 0 | F22: =COUNTIFS(專案清單!$B$2:$B$80,$B22,專案清單!$Q$2:$Q$80,F$16,專案清單!$R$2:$R$80,"主清單") -> 0 | G22: =COUNTIFS(專案清單!$B$2:$B$80,$B22,專案清單!$Q$2:$Q$80,G$16,專案清單!$R$2:$R$80,"主清單") -> 0 | H22: =SUM(C22:G22) -> 2
A23: TAS | B23: 塔斯馬尼亞州 | C23: =COUNTIFS(專案清單!$B$2:$B$80,$B23,專案清單!$Q$2:$Q$80,C$16,專案清單!$R$2:$R$80,"主清單") -> 0 | D23: =COUNTIFS(專案清單!$B$2:$B$80,$B23,專案清單!$Q$2:$Q$80,D$16,專案清單!$R$2:$R$80,"主清單") -> 0 | E23: =COUNTIFS(專案清單!$B$2:$B$80,$B23,專案清單!$Q$2:$Q$80,E$16,專案清單!$R$2:$R$80,"主清單") -> 0 | F23: =COUNTIFS(專案清單!$B$2:$B$80,$B23,專案清單!$Q$2:$Q$80,F$16,專案清單!$R$2:$R$80,"主清單") -> 0 | G23: =COUNTIFS(專案清單!$B$2:$B$80,$B23,專案清單!$Q$2:$Q$80,G$16,專案清單!$R$2:$R$80,"主清單") -> 0 | H23: =SUM(C23:G23) -> 0
A24: NT | B24: 北領地 | C24: =COUNTIFS(專案清單!$B$2:$B$80,$B24,專案清單!$Q$2:$Q$80,C$16,專案清單!$R$2:$R$80,"主清單") -> 0 | D24: =COUNTIFS(專案清單!$B$2:$B$80,$B24,專案清單!$Q$2:$Q$80,D$16,專案清單!$R$2:$R$80,"主清單") -> 0 | E24: =COUNTIFS(專案清單!$B$2:$B$80,$B24,專案清單!$Q$2:$Q$80,E$16,專案清單!$R$2:$R$80,"主清單") -> 0 | F24: =COUNTIFS(專案清單!$B$2:$B$80,$B24,專案清單!$Q$2:$Q$80,F$16,專案清單!$R$2:$R$80,"主清單") -> 0 | G24: =COUNTIFS(專案清單!$B$2:$B$80,$B24,專案清單!$Q$2:$Q$80,G$16,專案清單!$R$2:$R$80,"主清單") -> 0 | H24: =SUM(C24:G24) -> 0
A25: 合計 | C25: =SUM(C17:C24) -> 15 | D25: =SUM(D17:D24) -> 16 | E25: =SUM(E17:E24) -> 1 | F25: =SUM(F17:F24) -> 2 | G25: =SUM(G17:G24) -> 26 | H25: =SUM(H17:H24) -> 60
A27: 各州 × 完工時間窗（主清單件數）
A28: 州 | B28: 州名 | C28: 已可用／營運中 | D28: 2026 Q4 – 2027 Q2 | E28: 2027 下半年 | F28: 2028 年以後 | G28: 完工日未公布 | H28: 合計
A29: NSW | B29: 新南威爾斯州 | C29: =COUNTIFS(專案清單!$B$2:$B$80,$B29,專案清單!$X$2:$X$80,C$28,專案清單!$R$2:$R$80,"主清單") -> 3 | D29: =COUNTIFS(專案清單!$B$2:$B$80,$B29,專案清單!$X$2:$X$80,D$28,專案清單!$R$2:$R$80,"主清單") -> 1 | E29: =COUNTIFS(專案清單!$B$2:$B$80,$B29,專案清單!$X$2:$X$80,E$28,專案清單!$R$2:$R$80,"主清單") -> 2 | F29: =COUNTIFS(專案清單!$B$2:$B$80,$B29,專案清單!$X$2:$X$80,F$28,專案清單!$R$2:$R$80,"主清單") -> 6 | G29: =COUNTIFS(專案清單!$B$2:$B$80,$B29,專案清單!$X$2:$X$80,G$28,專案清單!$R$2:$R$80,"主清單") -> 21 | H29: =SUM(C29:G29) -> 33
A30: VIC | B30: 維多利亞州 | C30: =COUNTIFS(專案清單!$B$2:$B$80,$B30,專案清單!$X$2:$X$80,C$28,專案清單!$R$2:$R$80,"主清單") -> 0 | D30: =COUNTIFS(專案清單!$B$2:$B$80,$B30,專案清單!$X$2:$X$80,D$28,專案清單!$R$2:$R$80,"主清單") -> 3 | E30: =COUNTIFS(專案清單!$B$2:$B$80,$B30,專案清單!$X$2:$X$80,E$28,專案清單!$R$2:$R$80,"主清單") -> 1 | F30: =COUNTIFS(專案清單!$B$2:$B$80,$B30,專案清單!$X$2:$X$80,F$28,專案清單!$R$2:$R$80,"主清單") -> 3 | G30: =COUNTIFS(專案清單!$B$2:$B$80,$B30,專案清單!$X$2:$X$80,G$28,專案清單!$R$2:$R$80,"主清單") -> 14 | H30: =SUM(C30:G30) -> 21
A31: QLD | B31: 昆士蘭州 | C31: =COUNTIFS(專案清單!$B$2:$B$80,$B31,專案清單!$X$2:$X$80,C$28,專案清單!$R$2:$R$80,"主清單") -> 0 | D31: =COUNTIFS(專案清單!$B$2:$B$80,$B31,專案清單!$X$2:$X$80,D$28,專案清單!$R$2:$R$80,"主清單") -> 0 | E31: =COUNTIFS(專案清單!$B$2:$B$80,$B31,專案清單!$X$2:$X$80,E$28,專案清單!$R$2:$R$80,"主清單") -> 0 | F31: =COUNTIFS(專案清單!$B$2:$B$80,$B31,專案清單!$X$2:$X$80,F$28,專案清單!$R$2:$R$80,"主清單") -> 0 | G31: =COUNTIFS(專案清單!$B$2:$B$80,$B31,專案清單!$X$2:$X$80,G$28,專案清單!$R$2:$R$80,"主清單") -> 2 | H31: =SUM(C31:G31) -> 2
A32: WA | B32: 西澳州 | C32: =COUNTIFS(專案清單!$B$2:$B$80,$B32,專案清單!$X$2:$X$80,C$28,專案清單!$R$2:$R$80,"主清單") -> 0 | D32: =COUNTIFS(專案清單!$B$2:$B$80,$B32,專案清單!$X$2:$X$80,D$28,專案清單!$R$2:$R$80,"主清單") -> 1 | E32: =COUNTIFS(專案清單!$B$2:$B$80,$B32,專案清單!$X$2:$X$80,E$28,專案清單!$R$2:$R$80,"主清單") -> 0 | F32: =COUNTIFS(專案清單!$B$2:$B$80,$B32,專案清單!$X$2:$X$80,F$28,專案清單!$R$2:$R$80,"主清單") -> 1 | G32: =COUNTIFS(專案清單!$B$2:$B$80,$B32,專案清單!$X$2:$X$80,G$28,專案清單!$R$2:$R$80,"主清單") -> 0 | H32: =SUM(C32:G32) -> 2
A33: SA | B33: 南澳州 | C33: =COUNTIFS(專案清單!$B$2:$B$80,$B33,專案清單!$X$2:$X$80,C$28,專案清單!$R$2:$R$80,"主清單") -> 0 | D33: =COUNTIFS(專案清單!$B$2:$B$80,$B33,專案清單!$X$2:$X$80,D$28,專案清單!$R$2:$R$80,"主清單") -> 0 | E33: =COUNTIFS(專案清單!$B$2:$B$80,$B33,專案清單!$X$2:$X$80,E$28,專案清單!$R$2:$R$80,"主清單") -> 0 | F33: =COUNTIFS(專案清單!$B$2:$B$80,$B33,專案清單!$X$2:$X$80,F$28,專案清單!$R$2:$R$80,"主清單") -> 0 | G33: =COUNTIFS(專案清單!$B$2:$B$80,$B33,專案清單!$X$2:$X$80,G$28,專案清單!$R$2:$R$80,"主清單") -> 0 | H33: =SUM(C33:G33) -> 0
A34: ACT | B34: 首都領地 | C34: =COUNTIFS(專案清單!$B$2:$B$80,$B34,專案清單!$X$2:$X$80,C$28,專案清單!$R$2:$R$80,"主清單") -> 0 | D34: =COUNTIFS(專案清單!$B$2:$B$80,$B34,專案清單!$X$2:$X$80,D$28,專案清單!$R$2:$R$80,"主清單") -> 0 | E34: =COUNTIFS(專案清單!$B$2:$B$80,$B34,專案清單!$X$2:$X$80,E$28,專案清單!$R$2:$R$80,"主清單") -> 0 | F34: =COUNTIFS(專案清單!$B$2:$B$80,$B34,專案清單!$X$2:$X$80,F$28,專案清單!$R$2:$R$80,"主清單") -> 0 | G34: =COUNTIFS(專案清單!$B$2:$B$80,$B34,專案清單!$X$2:$X$80,G$28,專案清單!$R$2:$R$80,"主清單") -> 2 | H34: =SUM(C34:G34) -> 2
A35: TAS | B35: 塔斯馬尼亞州 | C35: =COUNTIFS(專案清單!$B$2:$B$80,$B35,專案清單!$X$2:$X$80,C$28,專案清單!$R$2:$R$80,"主清單") -> 0 | D35: =COUNTIFS(專案清單!$B$2:$B$80,$B35,專案清單!$X$2:$X$80,D$28,專案清單!$R$2:$R$80,"主清單") -> 0 | E35: =COUNTIFS(專案清單!$B$2:$B$80,$B35,專案清單!$X$2:$X$80,E$28,專案清單!$R$2:$R$80,"主清單") -> 0 | F35: =COUNTIFS(專案清單!$B$2:$B$80,$B35,專案清單!$X$2:$X$80,F$28,專案清單!$R$2:$R$80,"主清單") -> 0 | G35: =COUNTIFS(專案清單!$B$2:$B$80,$B35,專案清單!$X$2:$X$80,G$28,專案清單!$R$2:$R$80,"主清單") -> 0 | H35: =SUM(C35:G35) -> 0
A36: NT | B36: 北領地 | C36: =COUNTIFS(專案清單!$B$2:$B$80,$B36,專案清單!$X$2:$X$80,C$28,專案清單!$R$2:$R$80,"主清單") -> 0 | D36: =COUNTIFS(專案清單!$B$2:$B$80,$B36,專案清單!$X$2:$X$80,D$28,專案清單!$R$2:$R$80,"主清單") -> 0 | E36: =COUNTIFS(專案清單!$B$2:$B$80,$B36,專案清單!$X$2:$X$80,E$28,專案清單!$R$2:$R$80,"主清單") -> 0 | F36: =COUNTIFS(專案清單!$B$2:$B$80,$B36,專案清單!$X$2:$X$80,F$28,專案清單!$R$2:$R$80,"主清單") -> 0 | G36: =COUNTIFS(專案清單!$B$2:$B$80,$B36,專案清單!$X$2:$X$80,G$28,專案清單!$R$2:$R$80,"主清單") -> 0 | H36: =SUM(C36:G36) -> 0
A37: 合計 | C37: =SUM(C29:C36) -> 3 | D37: =SUM(D29:D36) -> 5 | E37: =SUM(E29:E36) -> 3 | F37: =SUM(F29:F36) -> 10 | G37: =SUM(G29:G36) -> 39 | H37: =SUM(H29:H36) -> 60
A39: 各州容量與資料品質（只計主清單）
A40: 州 | B40: 州名 | C40: 專案數（件） | D40: 已知容量（MW） | E40: 容量未公布（件） | F40: 可信度「高」（件） | G40: 占已知總容量
A41: NSW | B41: 新南威爾斯州 | C41: =COUNTIFS(專案清單!$B$2:$B$80,$B41,專案清單!$R$2:$R$80,"主清單") -> 33 | D41: =SUMIFS(專案清單!$M$2:$M$80,專案清單!$B$2:$B$80,$B41,專案清單!$R$2:$R$80,"主清單") -> 7526.6 | E41: =COUNTIFS(專案清單!$B$2:$B$80,$B41,專案清單!$M$2:$M$80,"未公布",專案清單!$R$2:$R$80,"主清單") -> 2 | F41: =COUNTIFS(專案清單!$B$2:$B$80,$B41,專案清單!$AD$2:$AD$80,"高",專案清單!$R$2:$R$80,"主清單") -> 27 | G41: =IF($D$49=0,0,D41/$D$49) -> 0.53020654
A42: VIC | B42: 維多利亞州 | C42: =COUNTIFS(專案清單!$B$2:$B$80,$B42,專案清單!$R$2:$R$80,"主清單") -> 21 | D42: =SUMIFS(專案清單!$M$2:$M$80,專案清單!$B$2:$B$80,$B42,專案清單!$R$2:$R$80,"主清單") -> 4233 | E42: =COUNTIFS(專案清單!$B$2:$B$80,$B42,專案清單!$M$2:$M$80,"未公布",專案清單!$R$2:$R$80,"主清單") -> 2 | F42: =COUNTIFS(專案清單!$B$2:$B$80,$B42,專案清單!$AD$2:$AD$80,"高",專案清單!$R$2:$R$80,"主清單") -> 15 | G42: =IF($D$49=0,0,D42/$D$49) -> 0.29819099
A43: QLD | B43: 昆士蘭州 | C43: =COUNTIFS(專案清單!$B$2:$B$80,$B43,專案清單!$R$2:$R$80,"主清單") -> 2 | D43: =SUMIFS(專案清單!$M$2:$M$80,專案清單!$B$2:$B$80,$B43,專案清單!$R$2:$R$80,"主清單") -> 1940 | E43: =COUNTIFS(專案清單!$B$2:$B$80,$B43,專案清單!$M$2:$M$80,"未公布",專案清單!$R$2:$R$80,"主清單") -> 0 | F43: =COUNTIFS(專案清單!$B$2:$B$80,$B43,專案清單!$AD$2:$AD$80,"高",專案清單!$R$2:$R$80,"主清單") -> 1 | G43: =IF($D$49=0,0,D43/$D$49) -> 0.13666206
A44: WA | B44: 西澳州 | C44: =COUNTIFS(專案清單!$B$2:$B$80,$B44,專案清單!$R$2:$R$80,"主清單") -> 2 | D44: =SUMIFS(專案清單!$M$2:$M$80,專案清單!$B$2:$B$80,$B44,專案清單!$R$2:$R$80,"主清單") -> 392 | E44: =COUNTIFS(專案清單!$B$2:$B$80,$B44,專案清單!$M$2:$M$80,"未公布",專案清單!$R$2:$R$80,"主清單") -> 0 | F44: =COUNTIFS(專案清單!$B$2:$B$80,$B44,專案清單!$AD$2:$AD$80,"高",專案清單!$R$2:$R$80,"主清單") -> 1 | G44: =IF($D$49=0,0,D44/$D$49) -> 0.02761419
A45: SA | B45: 南澳州 | C45: =COUNTIFS(專案清單!$B$2:$B$80,$B45,專案清單!$R$2:$R$80,"主清單") -> 0 | D45: =SUMIFS(專案清單!$M$2:$M$80,專案清單!$B$2:$B$80,$B45,專案清單!$R$2:$R$80,"主清單") -> 0 | E45: =COUNTIFS(專案清單!$B$2:$B$80,$B45,專案清單!$M$2:$M$80,"未公布",專案清單!$R$2:$R$80,"主清單") -> 0 | F45: =COUNTIFS(專案清單!$B$2:$B$80,$B45,專案清單!$AD$2:$AD$80,"高",專案清單!$R$2:$R$80,"主清單") -> 0 | G45: =IF($D$49=0,0,D45/$D$49) -> 0
...

Sheet 專案清單
A1: 編號 | B1: 州 | C1: 專案名稱 | D1: 營運商 | E1: 開發商／業主 | F1: 街道地址 | G1: 郊區 | H1: 郵遞區號 | I1: 區政府 | J1: 緯度 | K1: 經度 | L1: 座標精度 | M1: 容量 MW | N1: 容量口徑 | O1: 首期 MW | P1: 容量備註 | Q1: 狀態 | R1: 分級 | S1: 分級說明 | T1: 狀態日期 | U1: 施工證據 | V1: 開工時間 | W1: 預計完工（原文） | X1: 完工時間窗 | Y1: 完工日來源 | Z1: 可租判斷 | AA1: 可租備註 | AB1: 已知租戶 | AC1: 核准案號 | AD1: 可信度 | AE1: 差異／備註 | AF1: 政府來源 | AG1: 營運商來源 | AH1: 媒體來源 | AI1: 已讀原文來源 | AJ1: Google 地圖 | AK1: 回報代理
A2: VIC-001 | B2: 維多利亞州 | C2: CDC Brooklyn 園區（BK1／BK2 已營運，第三棟規劃中） | D2: CDC Data Centres | E2: CDC | F2: 598B Geelong Road, Brooklyn VIC 3012 | G2: Brooklyn | H2: 3012 | I2: Brimbank City Council（依 DCM wiki） | J2: -37.81667 | K2: 144.84641 | L2: 門牌級 | M2: 155 | N2: 口徑不明 | P2: DCD 2026-03-03：引述財政部長貼文稱新增 155 MW；CDC 官網稱完工後逾 350 MW；DCM wiki：BK1 逾 150 MW。 | Q2: 近期完工（仍有容量） | R2: 觀察名單 (出租性待確認) | S2: 出租性待確認：營運設施，未見公開剩餘容量；DCM wiki 稱 Firmus（Project Southgate）與 Meta 已佔用部分。 | T2: 2026-02-26 | U2: DJSIR 2026-02-26（已讀）：CDC 正式啟用 Brooklyn 園區，兩棟設施已運轉，第三棟規劃進行中。Brimbank 公開規劃登記冊（資料截至 2025-07-22，已讀並以座標核對）：P569/2023（598B Geelong Rd）『Development of part of the land for a data centre (second stage – north side) within DDO11 …』2023-11-08 受理、2024-02-20 由委派官員核發；P652/2021（598／598A／598B Geelong Rd）資料中心圖面修訂 2022-12-28 核發、紅線與停車變更 2022-06-21 核發。DCM wiki：BK1 於 2022-05 動工、2024-07 完工；BK2 於 2024-10 動工、約 2025 年底完工。第三棟尚無申請編號。 | V2: BK1 2022-05；BK2 2024-10（wiki） | W2: 第三棟未公布 | X2: 已可用／營運中 | Y2: — | Z2: 待確認 | AA2: 營運設施，未見公開剩餘容量；DCM wiki 稱 Firmus（Project Southgate）與 Meta 已佔用部分。 | AB2: Firmus（GB300 叢集）；Firmus 2026-09 稿稱終端客戶為 Meta（皆依 DCM wiki 轉述，未開啟 Firmus 原文） | AC2: Brimbank P569/2023（第二階段北側，2024-02-20 核發）；P652/2021（修訂，2022）；原始許可編號未取得 | AD2: 中 | AE2: CDC 官網（BK1 營運、其餘興建中）vs DJSIR 2026-02-26（兩座運作中）；350 MW 與變電站 99 MVA 數字不一致 地址備註：另含 11A McDonald Road, Brooklyn（DCM wiki）；Jemena 專用區域變電站在 598 Geelong Road（2023-09 完工）。 | AF2: https://djsir.vic.gov.au/news-and-articles/cdcs-data-centres-fueling-jobs-and-growth-in-the-west https://records.brimbank.vic.gov.au/ExternalLinkAPI/api/document/?docKey=UHZYRmNFYWVDaUN0clNmekJwVXhMUExwUGpQcFE0VVFXVnp1NkdSYlZpc0lsS2NCZlVOWUxOVXBncy9DSUhHZg2 | AG2: https://cdc.com/locations/melbourne/ | AH2: https://www.datacenterdynamics.com/en/news/australias-cdc-opens-data-center-campus-in-melbourne/ https://www.invest.vic.gov.au/news-and-events/news/2026/march/cdc-data-centres-officially-opens-its-first-melbourne-campus-expanding-its-ability-to-deliver-secure-and-sustainable-solutions https://datacentremoratorium.net/index.php/Resources:CDC_Brooklyn_Campus | AI2: https://djsir.vic.gov.au/news-and-articles/cdcs-data-centres-fueling-jobs-and-growth-in-the-west https://www.datacenterdynamics.com/en/news/australias-cdc-opens-data-center-campus-in-melbourne/ https://records.brimbank.vic.gov.au/ExternalLinkAPI/api/document/?docKey=UHZYRmNFYWVDaUN0clNmekJwVXhMUExwUGpQcFE0VVFXVnp1NkdSYlZpc0lsS2NCZlVOWUxOVXBncy9DSUhHZg2 https://datacentremoratorium.net/index.php/Resources:CDC_Brooklyn_Campus https://cdc.com/locations/melbourne/ | AJ2: 開啟地圖 | AK2: VIC-B、VIC-A
A3: NSW-001 | B3: 新南威爾斯州 | C3: Macquarie Technology IC3 Super West — Talavera Road Data Centre Campus Expansion（SSD-24299707） | D3: Macquarie Data Centres（Macquarie Technology Group） | E3: Macquarie Data Centres Pty Ltd（申請人） | F3: 17-23 Talavera Road, Macquarie Park NSW 2113 | G3: Macquarie Park | H3: 2113 | I3: City of Ryde | J3: -33.78073 | K3: 151.12733 | L3: 來源提供 | M3: 47 | N3: 耗電量 | O3: 6 | P3: 原核准（IPC，2024-01-19）38 MW；Mod 1（2024-12-19 核准）增至 47 MW，整個園區合計 66→75 MW。八層擴建、GFA 16,142 m2、20×3.3 MW 發電機。公司揭露（先前資料）：首批 6 MW IT 預計 2026-09 啟用、已有 A$50m 債務額度支應 19 MW 長交期設備；FY27 下半年起認列營收。 | Q3: 近期完工（仍有容量） | R3: 主清單 | T3: 2026-07-23 | U3: A15「Notification of Commencement」2024-01-24；Macquarie Telecom 施工通知 2024-05-22 與 2024-06-11；Stage 2 CEMP 核准 2024-06-27；「Commencement of Operations」函（2026-07-22；portal 上傳 2026-07-23）：Stage 2 預期約一個月後開始營運；FDC Construction 為總包（媒體，先前資料）。 | V3: 2024-01/2024-06（通知函） | W3: 評估報告：施工約 21 個月；Stage 2 營運 2026-08/09 起；後續階段（19 MW→47 MW）未公布日期。 | X3: 已可用／營運中 | Y3: DPHI/IPC Assessment Report（2023-11-27）；Macquarie 營運通知（2026-07-22） | Z3: 可租 | AA3: Macquarie Data Centres 為主權級託管營運商，向企業、政府出租；本期容量逐階段釋出，是 5–20 MW 規模的近期可談標的。 | AB3: 未揭露 | AC3: SSD-24299707（IPC 核准 2024-01-19）；Mod 1（2024-12-19） | AD3: 高 | AE3: 地址 17-23 vs 33-39 Talavera Road（Khartoum 報告）；容量 38/47 MW（兩次核准）；先前資料 47 MW 為「total」，實為本次擴建增量，園區合計 75 MW；先前資料寫首期 6 MW 於 2026-09 啟用；ASX 簡報（2026-08-26）仍屬預告，截至 2026-10-03 是否已啟用未取得公司確認 地址備註：Lot 527 DP 752035 與 Part Lot 3 DP 1043041，約 2 公頃；Khartoum Road 評估報告把同一 SSD 寫成「33-39 Talavera Road」。 | AF3: https://www.planningportal.nsw.gov.au/major-projects/projects/talavera-road-data-centre-campus-expansion https://majorprojects.planningportal.nsw.gov.au/prweb/PRRestService/mp/01/getContent?AttachRef=SSD-24299707%2120231127T020928.161+GMT https://majorprojects.planningportal.nsw.gov.au/prweb/PRRestService/mp/01/getContent?AttachRef=SSD-24299707-PA-22%2120260723T112244.245+GMT https://majorprojects.planningportal.nsw.gov.au/prweb/PRRestService/mp/01/getContent?AttachRef=SSD-24299707-MOD-1%2120241219T224421.352+GMT https://www.planningportal.nsw.gov.au/major-projects/projects/talavera-road-data-centre-mod-1-expansion | AG3: https://cdn-api.markitdigital.com/apiman-gateway/ASX/asx-research/1.0/file/2924-03126655-2A1692379 | AH3: https://baxtel.com/data-center/macquarie-ic3-super-west | AI3: https://www.planningportal.nsw.gov.au/major-projects/projects/talavera-road-data-centre-campus-expansion https://majorprojects.planningportal.nsw.gov.au/prweb/PRRestService/mp/01/getContent?AttachRef=SSD-24299707%2120231127T020928.161+GMT https://majorprojects.planningportal.nsw.gov.au/prweb/PRRestService/mp/01/getContent?AttachRef=SSD-24299707-PA-22%2120260723T112244.245+GMT https://majorprojects.planningportal.nsw.gov.au/prweb/PRRestService/mp/01/getContent?AttachRef=SSD-24299707-MOD-1%2120241219T224421.352+GMT https://www.planningportal.nsw.gov.au/major-projects/projects/talavera-road-data-centre-mod-1-expansion https://cdn-api.markitdigital.com/apiman-gateway/ASX/asx-research/1.0/file/2924-03126655-2A1692379 | AJ3: 開啟地圖 | AK3: NSW-B、NSW-A
A4: VIC-002 | B4: 維多利亞州 | C4: AirTrunk MEL1（Derrimut）— 營運中，疑有擴建 | D4: AirTrunk | E4: AirTrunk（Blackstone／CPP Investments 控股） | F4: 176 Swann Drive, Derrimut VIC 3026 | G4: Derrimut | H4: 3026 | I4: Brimbank City Council | J4: -37.801761 | K4: 144.77557 | L4: 街道級 | M4: 276 | N4: 口徑不明 | P4: AirTrunk 官網（已讀）：185+ MW；AirTrunk 2025-12-24 新聞稿：MEL1 276 MW+，兩者差約 91 MW，與 Brimbank 2025-04 核發的『新增兩階段』相符，推測為新增棟別。 | Q4: 已營運（有餘裕／擴建） | R4: 觀察名單 (出租性待確認) | S4: 出租性待確認：AirTrunk 為超大規模批發型；未見可租空置容量的公開數字。 | T4: 2025-12-24 | U4: Brimbank 公開規劃登記冊（資料截至 2025-07-22，已讀並以座標核對）：P490/2016（Pt 3）涵蓋 31 Jilly Ct、156 與 176 Swann Dr，2024-12-23 受理的修訂內容為『將地址擴充、許可內容加入移除原生植被、修訂圖面以詳述建物與工程並新增兩個階段（add two new stages）』，2025-04-09 由委派官員核發修訂許可；另 P82/2019（210 Swann Dr 『use and staged development of the land for a data centre』）2019-08-30 核發。登記冊未具名 AirTrunk，營運商身分取自 DCM wiki 對這些地址的標註。尚無具日期的施工事件。 | V4: 未公布 | W4: 未公布 | X4: 已可用／營運中 | Y4: — | Z4: 待確認 | AA4: AirTrunk 為超大規模批發型；未見可租空置容量的公開數字。 | AB4: 未公布（DCM wiki 列 Datacom 為共同開發方） | AC4: Brimbank P490/2016（Pt 3，新增兩階段，2025-04-09 核發修訂）；P82/2019（210 Swann Dr，2019-08-30） | AD4: 中 | AE4: 185+ MW（官網）vs 276+ MW（新聞稿）；185+ MW（官網頁）vs 276 MW+（2025-12 新聞稿）；DCM wiki 亦列 185 MW。 地址備註：DCM wiki 列 176 Swann Drive、156 Swann Drive、31 Jilly Court（Brimbank 議會申請）；AirTrunk 官網只稱「墨爾本西部」未列街址；realestatesource 稱 MEL1 在 Derrimut、34 個機房。 | AF4: https://records.brimbank.vic.gov.au/ExternalLinkAPI/api/document/?docKey=UHZYRmNFYWVDaUN0clNmekJwVXhMUExwUGpQcFE0VVFXVnp1NkdSYlZpc0lsS2NCZlVOWUxOVXBncy9DSUhHZg2 | AG4: https://airtrunk.com/data-centres/mel1/ https://airtrunk.com/airtrunk-expands-australian-platform-with-a-second-hyperscale-data-centre-campus-in-melbourne/ https://airtrunk.com/location/mel1-melbourne/ | AH4: https://www.realestatesource.com.au/data-centre-giant-buys-350m-melbourne-site/ | AI4: https://airtrunk.com/data-centres/mel1/ https://airtrunk.com/airtrunk-expands-australian-platform-with-a-second-hyperscale-data-centre-campus-in-melbourne/ https://records.brimbank.vic.gov.au/ExternalLinkAPI/api/document/?docKey=UHZYRmNFYWVDaUN0clNmekJwVXhMUExwUGpQcFE0VVFXVnp1NkdSYlZpc0lsS2NCZlVOWUxOVXBncy9DSUhHZg2 https://datacentremoratorium.net/index.php/Resources:AirTrunk_MEL1 https://airtrunk.com/location/mel1-melbourne/ https://www.realestatesource.com.au/data-centre-giant-buys-350m-melbourne-site/ https://datacentremoratorium.net/index.php/Resources:Data_Centres_in_Greater_Melbourne | AJ4: 開啟地圖 | AK4: VIC-B、VIC-A
A5: NSW-002 | B5: 新南威爾斯州 | C5: Southern Highlands Data Campus (SHDC) — Data Building One (DB1) | D5: Cloud Carrier (Cloud Carrier Operations Pty Ltd) | E5: Nakar Property Pty Ltd（地主／開發商，Bella Vista）；Square Energy Pty Ltd（園區燃氣發電） | F5: 30 Douglas Road, Moss Vale NSW 2577 | G5: Moss Vale | H5: 2577 | I5: Wingecarribee Shire | J5: -34.515334 | K5: 150.36982 | L5: 門牌級 | M5: 28 | N5: 耗電量 | P5: Cloud Carrier DB1 頁面列『Total Power 28MW』、Data Hall 1,850 sqm、Deployment: Powered Shell、DLC 140 kW+/rack、PUE <1.15（IT 負載未明示，故標 power_consumption）。2024-09 發表時 DB1 為 15 MW，園區最終可擴至 300 MW（W.Media 2024-09-27）。園區自建燃氣發電（官網稱數百 MW、脫離電網）。 | Q5: 已營運（有餘裕／擴建） | R5: 主清單 | T5: 2025-09 | U5: Nakar Property 範疇界定報告（Western Sydney Planning，2025-09，Planning Portal）：DA 21/1042（Wingecarribee 議會 2021-02-25 核准，已修改兩次）之後『the first data building (DB1) has now been constructed』。未見第三方確認通電日期、營運狀態或租戶；Cloud Carrier 官網以『Powered Shell』方式行銷 DB1。 | V5: DA 21/1042 於 2021-02-25 核准；確切動工日未知 | W5: DB1：2025-09 報告稱已建成；DB2 官網標示 coming soon | X5: 已可用／營運中 | Y5: Nakar Property 範疇界定報告 2025-09（Planning Portal）；Cloud Carrier 官網 | Z5: 可租 | AA5: 官網載明園區提供『Scalable Powered Shell Solutions』、載體中立、服務政府與企業客戶，屬可出租（powered shell／colocation）。尚無公開租戶，是否仍有 >=5 MW 未租出容量為合理推定，非明確證據。 | AB5: 未公開 | AC5: Wingecarribee Council DA 21/1042（DB1，2021-02-25）；DA 24/0055（14 MW 燃氣發電，2024-04-19 核准）；DA 26/0352（燃氣發電，2025-09-11 遞交）；SSD-102795459（673.2 MW 燃氣發電廳，SEARs 2025-12-22） | AD5: 中 | AE5: (1) DB1 容量：W.Media 2024-09-27 為 15 MW；Cloud Carrier 官網現列 Total Power 28 MW。(2) 園區上限：2024 稱 300 MW 地址備註：Cloud Carrier 官網聯絡頁載明 Campus: Southern Highlands Data Campus, 30 Douglas Road, Moss Vale NSW 2577；範疇界定報告：Lot 40 DP 1288692，約 67 ha。DB1、DB2 與後續建築皆在同一地址。 | AF5: https://www.planningportal.nsw.gov.au/major-projects/projects/southern-highlands-data-campus-power-station https://majorprojects.planningportal.nsw.gov.au/prweb/PRRestService/mp/01/getContent?AttachRef=PDA-95012491%2120250926T033914.129+GMT https://majorprojects.planningportal.nsw.gov.au/prweb/PRRestService/mp/01/getContent?AttachRef=SSD-102795459%2120251222T014859.011+GMT | AG5: https://cloudcarrier.com/campus/ https://cloudcarrier.com/db1/ https://cloudcarrier.com/contact-us/ | AH5: https://w.media/cloud-carrier-launches-australias-first-liquid-cooled-data-campus-in-the-southern-highlands/ | AI5: https://www.planningportal.nsw.gov.au/major-projects/projects/southern-highlands-data-campus-power-station https://majorprojects.planningportal.nsw.gov.au/prweb/PRRestService/mp/01/getContent?AttachRef=PDA-95012491%2120250926T033914.129+GMT https://cloudcarrier.com/ https://cloudcarrier.com/campus/ https://cloudcarrier.com/db1/ https://cloudcarrier.com/contact-us/ https://cloudcarrier.com/about-us/ https://w.media/cloud-carrier-launches-australias-first-liquid-cooled-data-campus-in-the-southern-highlands/ https://majorprojects.planningportal.nsw.gov.au/prweb/PRRestService/mp/01/getContent?AttachRef=SSD-102795459%2120251222T014859.011+GMT | AJ5: 開啟地圖 | AK5: NSW-C、NSW-B
A6: VIC-003 | B6: 維多利亞州 | C6: Fujitsu Noble Park 資料中心（Next Capital 收購中） | D6: Fujitsu Australia（現營運）；Next Capital 於 2026-07-20 簽約收購，預計 2026 下半年交割 | E6: Fujitsu 自有土地與建物（DCD：owned and operated by Fujitsu）；買方為 Next Capital 第五期基金（A$3.75 億） | F6: 5 Summit Road (3-5 Summit Road), Noble Park North VIC 3174 | G6: Noble Park North | H6: 3174 | I6: City of Greater Dandenong（推定，未經官方來源確認） | J6: -37.947699 | K6: 145.18577 | L6: 來源提供 | M6: 12 | N6: 口徑不明 | P6: AFR（經 DCD 2026-07-20）稱 Noble Park 為 12MW；五站合計 25MW、約 7MW 已租給約 130 家客戶，即整體約 18MW 未租（推算），並稱可擴至合計 100MW（主要指 Greystanes 最高 60MW）。站點層級的已租或空置量未公布。Fujitsu 規格（Baxtel）：2 x 4MVA 主進線、2 x 1,800kW 柴油旋轉 UPS（N+1）、2,400kW 靜態 UPS、3 x 1,800kW 發電機（N+1），以此推算受保護 IT 容量遠低於 12MW，與 AFR 數字不一致。 | Q6: 已營運（有餘裕／擴建） | R6: 觀察名單 (出租性待確認) | S6: 出租性待確認：既有 Fujitsu 對外出租的主機代管/託管設施，Next Capital 計畫整合為獨立澳洲平台並擴建；但站點層級 5MW 以上的空置容量缺乏公開證據，列入僅為回應 先前 對 Noble Park 的查詢。 | T6: 2026-07-20 | U6: 不適用（既有 1988 年建、2015 年升級的營運中設施）。DCD 與 Fujitsu 聲明：交割前一切照常營運。 | V6: 不適用 | W6: 不適用（交易預計 2026 下半年完成，不含 North Ryde） | X6: 已可用／營運中 | Y6: DCD 2026-07-20（引 AFR 與 Fujitsu LinkedIn 聲明） | Z6: 待確認 | AA6: 既有 Fujitsu 對外出租的主機代管/託管設施，Next Capital 計畫整合為獨立澳洲平台並擴建；但站點層級 5MW 以上的空置容量缺乏公開證據，列入僅為回應 先前 對 Noble Park 的查詢。 | AB6: 約 130 家客戶（五站合計，AFR 經 DCD）；無單一大租戶公布 | AC6: 不適用 | AD6: 低 | AE6: 容量：AFR/DCD 12MW 對 Fujitsu 電氣規格（進線 2 x 4MVA、UPS 與發電機約 1.8-3.6MW 級）不一致；面積：DCD 3,600 平方公尺，Baxtel 引 Fujitsu 稱機房 3,800 平方公尺、建物 6,700 平方公尺。Next Capital 官網新聞稿未提供站點街址或容量（已開啟閱讀） 地址備註：Baxtel 標示 5 Summit Rd；DatacenterMap 標示 3-5 Summit Road（其頁面郵遞區號誤植為 3101）；OSM 建物標籤為 Fujitsu Data Centre, 3-5 Summit Road, Noble Park North 3174。土地 18,400 平方公尺、建物 6,700 平方公尺、機房 3,800 平方公尺（Baxtel 引 Fujitsu 規格）。 | AG6: https://nextcapital.com.au/next-capital-buys-fujitsu-australian-data-centres/ | AH6: https://www.datacenterdynamics.com/en/news/fujitsu-sells-australian-data-center-business-to-next-capital/ https://baxtel.com/data-center/fujitsu-noble-park https://www.datacentermap.com/australia/melbourne/fujitsu-melbourne/ | AI6: https://www.datacenterdynamics.com/en/news/fujitsu-sells-australian-data-center-business-to-next-capital/ https://baxtel.com/data-center/fujitsu-noble-park https://www.datacentermap.com/australia/melbourne/fujitsu-melbourne/ https://nextcapital.com.au/next-capital-buys-fujitsu-australian-data-centres/ https://nominatim.openstreetmap.org/search?q=5+Summit+Road+Noble+Park+VIC | AJ6: 開啟地圖 | AK6: VIC-C、VIC-A
A7: NSW-003 | B7: 新南威爾斯州 | C7: Fujitsu Greystanes Data Centre（出售予 Next Capital） | D7: Fujitsu Australia → Next Capital（簽約 2026-07-20，預計 2026 稍後交割） | E7: Next Capital（買方，透過其第五支基金） | F7: 6 Bellevue Circuit, Pemulwuy (Greystanes) NSW 2145 | G7: Pemulwuy | H7: 2145 | I7: 未確認（Cumberland 或 Parramatta） | J7: -33.8219 | K7: 150.9238 | L7: 來源提供 | M7: 未公布 | N7: 口徑不明 | P7: 媒體稱 Greystanes 場址潛力最高 60 MW，不是現有可用容量；Fujitsu 五站組合合計約 25 MW、約 7 MW 已租、可擴建到 100 MW。各站現況容量與空置量未公布。 | Q7: 已營運（有餘裕／擴建） | R7: 主清單 | T7: 2026-07-20 | U7: 非建設案。Next Capital 表示交割後將投資擴建並逐站評估擴充，但未公布投資額或容量目標；無申請或開工證據。 | V7: — | W7: 交割預計 2026 年稍後；擴建無時程 | X7: 已可用／營運中 | Y7: W.Media／Fujitsu／Next Capital 2026-07-20 | Z7: 可租 | AA7: Fujitsu 資料中心業務為 colocation 與託管服務；買方稱『available capacity and significant growth potential』。 | AB7: 約 130 家客戶（含政府機關）；Fujitsu 交割後仍為客戶 | AD7: 低 | AE7: 『up to 60MW』與整體組合 25 MW 容量矛盾；本場址的未租出容量沒有公開數字，列入是因為買方明確以『available capacity』與擴建作賣點。無街道地址。 地址備註：新聞只稱 Greystanes，未載街道；該場址為承租物業（leased），非 Fujitsu 自有。需查 Fujitsu／Next Capital 官方資料取得地址。 | AH7: https://w.media/next-capital-agrees-to-acquire-fujitsus-australian-data-centre-business/ https://bebeez.eu/2026/07/20/fujitsu-sells-australian-data-center-business-to-next-capital/ | AI7: https://w.media/next-capital-agrees-to-acquire-fujitsus-australian-data-centre-business/ https://bebeez.eu/2026/07/20/fujitsu-sells-australian-data-center-business-to-next-capital/ | AJ7: 開啟地圖 | AK7: NSW-C
A8: VIC-004 | B8: 維多利亞州 | C8: STACK MEL02（Truganina；Baxtel 另列 MEL02A/MEL02B） | D8: STACK Infrastructure | E8: STACK Infrastructure（2022 年接手 Hickory 的開發案）；施工方 Hickory（據 DCM wiki） | F8: 411 Palmers Road, Truganina VIC 3029 | G8: Truganina | H8: 3029 | I8: Wyndham City Council | J8: -37.817386 | K8: 144.7494 | L8: 門牌級 | M8: 252 | N8: 關鍵負載 | P8: STACK 官網 MEL02 頁（已讀）：標題「250MW of critical capacity」，內文 252 MW、單一建築、227,000 sq ft（21,000 m²）技術面積、14 英畝、自有 132 kV 變電站（總容量 300+ MW）。Baxtel 把 MEL02 拆成 MEL02A（2026 建成）與 MEL02B（2027 規劃），與 STACK 官網的「1 building」不一致。 | Q8: 施工中 | R8: 主清單 | T8: 2026-05-12 | U8: Wyndham 規劃許可 WYP14917/24（2024-12-20 提出、2025-07-04 核發）；S72 修改 WYP14917/24.05 於 2026-05-12 核發（PlanningAlerts 已讀）。建築許可序列（依 DCM wiki 整理 Wyndham 紀錄；wiki 標註部分核發日早於提出日，日期僅供參考）：拆除 2025-07-30；樁基與地下管線前置工程 2025-09；主體結構（地面及 L1 樓板、地面至 L5 垂直構件）2025-12；變電站與 6 座變壓器防火牆 2026-02；新變電站與室內裝修 2026-03。 | V8: 2025-07（拆除許可 2025-07-30） | W8: MEL02A：2026（Baxtel）；MEL02B：2027（Baxtel） | X8: 2026 Q4 – 2027 Q2 | Y8: Baxtel（聚合器）；STACK 未公布日期 | Z8: 可租 | AA8: STACK 為批發/超大規模出租業者，MEL02 未公布租戶；是否能分租 5 MW 須直接詢問。 | AB8: 未公布 | AC8: Wyndham WYP14917/24（.05 修改）；MPA26/0049（TfV 轉介，2026-04-27） | AD8: 中 | AE8: STACK 官網 1 棟 252 MW vs Baxtel MEL02A + MEL02B 兩階段；Baxtel 另列 MEL02A／MEL02B 分棟；STACK 官網僅列單棟 252 MW。 地址備註：取自 Wyndham 申請 WYP14917/24.05（PlanningAlerts 頁面「411 Palmers Road Truganina」）；STACK MEL01 在同路 369-399 Palmers Road。 | AF8: https://planningalerts.org.au/applications/3442743 https://www.planningalerts.org.au/applications/3442743 | AG8: https://www.stackinfra.com/locations/asia-pacific/melbourne/mel02/ | AH8: https://baxtel.com/data-center/stack-melbourne-mel02 https://baxtel.com/data-center/stack-mel02b https://datacentremoratorium.net/index.php/Resources:STACK_MEL02_Campus https://www.datacenterdynamics.com/en/news/stack-tops-out-swiss-data-center-completes-construction-in-melbourne/ | AI8: https://planningalerts.org.au/applications/3442743 https://www.stackinfra.com/locations/asia-pacific/melbourne/mel02/ https://baxtel.com/data-center/stack-melbourne-mel02 https://baxtel.com/data-center/stack-mel02b https://datacentremoratorium.net/index.php/Resources:STACK_MEL02_Campus https://www.planningalerts.org.au/applications/3442743 https://www.datacenterdynamics.com/en/news/stack-tops-out-swiss-data-center-completes-construction-in-melbourne/ | AJ8: 開啟地圖 | AK8: VIC-A、VIC-B
A9: WA-001 | B9: 西澳州 | C9: CDC Maddington Campus (MA1-MA4), Perth | D9: CDC Data Centres (CDC) | E9: CDC Data Centres（股東：Infratil 49.72%，Infratil ASX 2026-07-06；澳洲 Future Fund 約 34.6%，The West Australian 2025-08-11） | F9: 307, 323 and 329 Kenwick Road and 582 Bickley Road, Maddington WA 6109 | G9: Maddington | H9: 6109 | I9: City of Gosnells | J9: -32.030017 | K9: 115.99953 | L9: 街道級 | M9: 200 | N9: 口徑不明 | O9: 34 | P9: (1) 園區總量：CDC 新聞稿（2025-08-11/12）稱完成後 up to 200 megawatts of high-density capacity；The West Australian 2025-09-10 稱獲批設施需約 200 MW 電力；Gosnells 市長 Terresa Lynes 於 ABC（2026-08-13）稱 eventually a 200-megawatt data centre。CDC 未說明是 IT 還是電力口徑。(2) 第一階段：Infratil/CDC 的 ASX 簡報（2026-05-05 公告第 4 頁；FY26 業績 2026-05-26 簡報第 11 頁，即 PDF 第 16 頁）標示 Perth 在建 34 MW（built MW，截至 2026-03-31），應為第一棟 MA1；同一簡報另列 Perth future build 至 FY34 為 101 MW，兩者合計 135 MW，低於 200 MW 標稱（口徑或範圍差異，未釐清）。(3) 2026-09-16 Infratil Investor Day 起改以 leasable capacity（ICT MW）披露，Perth 未另列 MW。(4) 首期投資 A$415m（CDC，2025-08）。(5) 全園區四棟二層樓，最高 24 m（CDC 官網）。 | Q9: 施工中 | R9: 主清單 | T9: 2026-09-16 | U9: (1) CDC 官網時間軸：DA 2025-09 核准、2025-10 場地整備與早期工程開始、2025-12 主體工程開始、2026-10 開始機房 fit-out、2027-01 開始營運。(2) CDC Maddington Project update September 2026（PDF，已讀）：第一棟（四棟之首）外殼幾乎完成、第一台塔吊已拆除、第二台本月拆除、永久電力已接通、污水管接駁即將開工、今年稍後開始系統測試。(3) Infratil Investor Day 簡報（ASX 2026-09-16；CDC 部分頁碼 6、9，即 PDF 第 105、108 頁）：第 6 頁 MA1 標示為在建、MA2 標示為 future development - land secured（以圖例顏色目視判讀）；第 9 頁附 Maddington 施工照片，稱 structure of CDC's inaugural Perth data centre nearing completion。(4) 政府：Metro Outer DAP 於 2025-09-10 核准（The West Australian、Business News 2025-09-10；Gosnells 市長 ABC 2026-08-13 證實 2025 年 9 月核准）。(5) CDC COO Glenn Uidam 於 2026-09-18 對 The West Australian 稱 Maddington 已施工數月，預計三四個月內開始營運。 | V9: 2025-10（場地整備與早期工程）；2025-12（主體工程） | W9: MA1：2027-01 開始營運（CDC 官網）；early 2027（CDC Project update 2026-09）。MA2-MA4：無官方日期（Baxtel 稱 Building 3 計畫 2029，屬聚合站，僅供參考）。 | X9: 2026 Q4 – 2027 Q2 | Y9: 營運商 CDC 官網及 Project update September 2026（一手，2026-10-03 讀取）；Infratil Investor Day（ASX 2026-09-16）稱在建資料中心將於 FY27-29 交付。 | Z9: 大概可租 | AA9: CDC 是批發型出租營運商，但對台灣租戶有三項保留：(a) Infratil 2026-09-16 稱 CDC 在已簽約容量的地點全面施工，MA1（34 MW）很可能已被預租（推論，原文未明說）；(b) CDC COO 於 2026-09-18 對 The West Australian 稱 CDC 主要服務政府機構與水電等關鍵基礎設施營運商，並表示對不在核心範圍的客戶會說不；(c) 目前只有 MA1 在建，MA2 為土地已取得的未來開發，MA3-MA4 無資訊。 | AB9: Maddington 尚無公開具名租戶。CDC 全國客戶包括 RBA、CSIRO、Western Sydney Airport（The West Australian 2025-08-11）；CDC 稱 Maddington 針對政府、研究、國防、關鍵基礎設施客戶。 | AC9: Metro Outer DAP 2025-09-10 核准（City of Gosnells 建議核准）；DAP 申請編號未取得。The West Australian 2025-08-11 稱 CDC 於 2025-06 提出 DA。 | AD9: 高 | AE9: (1) 容量：CDC 稱最高 200 MW，Infratil 披露 Perth 在建 34 MW + 未來 101 MW = 135 MW（built MW，2026-03-31）。(2) 營運時間：2025-08 的 DCD/W.Media/Baxtel 稱 2026 年營運，CDC 官網與 2026-09 update 為 2027-01 / early 2027，以後者為準。(3) 地址：DatacenterMap 稱 307 Kenwick Rd，CDC 稱 Bickley Road 旁，無法調和。(4) 已知事實清單所稱 first building operational Jan 2027 與 CDC 官網一致，確認無誤。(5) 付費牆：The West Australian 與 Business News 僅讀到前段；(1) 金額：媒體（W.Media／Baxtel 2025-08）稱 A$415m 為第一階段投資，但 DAP 報告 Form 1 的 Value of Development 為 A$415m 且涵蓋全部四棟，口徑不同。(2) 營運時間：2025-08 媒體稱 2026 年營運，CDC 2026-09 官方更新改為 2027 年初，以後者為準。(3) 棟數／面積：Baxtel 稱 3 棟、19 英畝；DAP 文件為 4 棟、基地 76,037 sqm（約 18.8 英畝）。(4) 容量：CDC 稱完成後 200 MW，而 Infratil 圖表只顯示 Perth 在建 34 MW（WA-A 另引 future build 101 MW，合計 135 MW，與 200 MW 有差距，口徑未釐清） 地址備註：DAP/25/02926 地址為 Lots 1, 10, 1 (No. 307, 323, 329) Kenwick Road 與 Lot 500 (No. 582) Bickley Road，核准條件要求合併為單一地契；基地約 76,037 sqm（7.6 ha），位於 Kelvin Road 與 Kenwick Road 轉角，緊鄰 Tonkin Highway；CDC 對外只稱『the industrial area off Bickley Road』。屬 Maddington Kenwick Strategic Employment Area（MKSEA）Precinct 1。變電站在圖上標示 By Others，不含在本次核准內，需另案提出 DA。先前資料 所引 DatacenterMap 的 307 Kenwick Rd 即上述 Lot 1，已由 DAP 文件證實。 | AF9: https://announcements.asx.com.au/asxpdf/20260916/pdf/074490wlf78g7n.pdf https://announcements.asx.com.au/asxpdf/20260526/pdf/06zymgqsx9p9y5.pdf https://announcements.asx.com.au/asxpdf/20260505/pdf/06z8f5lpdqcb57.pdf https://www.planning.wa.gov.au/docs/default-source/daps/minutes---no-102---city-of-gosnells.pdf?sfvrsn=9164d69f_1 https://www.planning.wa.gov.au/docs/default-source/daps/agenda---no-102---city-of-gosnells.pdf?sfvrsn=36d5cb68_1 https://www.planning.wa.gov.au/docs/default-source/daps/related-information---no-102---part-b---city-of-gosnells.pdf?sfvrsn=f47a3ead_1 https://www.planning.wa.gov.au/development-assessment-panels/daps-agendas-and-minutes/metro-outer-agenda-and-minutes | AG9: https://cdc.com/locations/perth/maddington/ https://cdc.com/media/4y2fcog4/maddington-project-update-september-2026.pdf https://cdc.com/locations/perth/ https://cdc.com/resources/news/cdc-announces-landmark-plan-to-drive-ai-and-advanced-technology-deployments-in-western-australia/ https://www.cdc.com/maddington | AH9: https://thewest.com.au/business/construction/maddington-data-centre-development-green-light-for-415m-project-and-construction-tipped-to-start-soon-c-19977544 https://thewest.com.au/business/infrastructure/cdc-data-centres-unveils-plans-for-415m-maddington-data-centre-c-19636890 https://www.businessnews.com.au/article/Maddington-s-415m-data-centre-approved https://www.abc.net.au/news/2026-08-13/councils-grapple-with-data-centre-applications/107029724 https://www.yourlocalexaminer.com.au/have-your-say-on-data-centre/ https://w.media/cdc-data-centres-plans-was-largest-ai-and-advanced-technology-campus/ https://www.datacenterdynamics.com/en/news/australias-cdc-plans-200mw-data-center-campus-outside-perth/ https://baxtel.com/data-center/cdc-maddington-perth https://baxtel.com/news/cdc-plans-200mw-data-center-campus-outside-perth https://www.projectory.com.au/article/415m-data-centre-development-approved-in-wa-to-support-digital-infrastructure-and-advanced-tech-capabilities https://renewmap.com.au/resources/projects/wa/datacentre/ | AI9: https://cdc.com/locations/perth/maddington/ https://cdc.com/media/4y2fcog4/maddington-project-update-september-2026.pdf https://cdc.com/locations/perth/ https://cdc.com/resources/news/cdc-announces-landmark-plan-to-drive-ai-and-advanced-technology-deployments-in-western-australia/ https://announcements.asx.com.au/asxpdf/20260916/pdf/074490wlf78g7n.pdf https://announcements.asx.com.au/asxpdf/20260526/pdf/06zymgqsx9p9y5.pdf https://announcements.asx.com.au/asxpdf/20260505/pdf/06z8f5lpdqcb57.pdf https://www.abc.net.au/news/2026-08-13/councils-grapple-with-data-centre-applications/107029724 https://www.yourlocalexaminer.com.au/have-your-say-on-data-centre/ https://thewest.com.au/business/construction/maddington-data-centre-development-green-light-for-415m-project-and-construction-tipped-to-start-soon-c-19977544 https://thewest.com.au/business/infrastructure/cdc-data-centres-unveils-plans-for-415m-maddington-data-centre-c-19636890 https://w.media/cdc-data-centres-plans-was-largest-ai-and-advanced-technology-campus/ https://www.datacenterdynamics.com/en/news/australias-cdc-plans-200mw-data-center-campus-outside-perth/ https://www.projectmanagementplanet.com.au/post/cdcs-maddington-data-centre https://baxtel.com/data-center/cdc-maddington-perth https://www.planning.wa.gov.au/docs/default-source/daps/minutes---no-102---city-of-gosnells.pdf?sfvrsn=9164d69f_1 https://www.planning.wa.gov.au/docs/default-source/daps/agenda---no-102---city-of-gosnells.pdf?sfvrsn=36d5cb68_1 https://www.cdc.com/maddington https://baxtel.com/news/cdc-plans-200mw-data-center-campus-outside-perth https://renewmap.com.au/resources/projects/wa/datacentre/ | AJ9: 開啟地圖 | AK9: WA-A、WA-B
A10: VIC-005 | B10: 維多利亞州 | C10: STACK MEL01C + MEL01D（Truganina；MEL01 園區第三、四棟） | D10: STACK Infrastructure | E10: STACK Infrastructure；施工方 Hickory | F10: 399 Palmers Road, Truganina VIC 3029 | G10: Truganina | H10: 3029 | I10: Wyndham City Council | J10: -37.819933 | K10: 144.74764 | L10: 門牌級 | M10: 108 | N10: 口徑不明 | O10: 54 | P10: STACK 官網 MEL01 頁（已讀）：園區 180 MW、4 棟；MEL01A、B 各 36 MW（已營運）；MEL01C、D 各 54 MW（各 506,000 sq ft）；園區變電站 66kV/11kV、總容量 135 MW。108 MW = 2×54。 | Q10: 施工中 | R10: 主清單 | T10: 2025-11-26 | U10: STACK 官網 MEL01 頁：園區 180 MW、四棟（A、B 各 36 MW 已營運；C、D 各 54 MW），未載各棟狀態。DCD 2025-11-26：MEL01B 竣工，C/D 各 54 MW。承建商 Hickory 專案頁把『MEL01C&D』列在『Completed』類別（該頁稱位於 Laverton、單一三層建築，與 STACK 官網的 Truganina、兩棟不符），可能是土建完成、機電與啟用仍在進行。Baxtel：MEL01C 2026 年建成。缺少政府開工文件，需向 STACK 確認。 | V10: 未確認（2025-07 之後） | W10: MEL01C：2026-Q4；MEL01D：2027-Q2 | X10: 2026 Q4 – 2027 Q2 | Y10: Baxtel（聚合器；先前資料列 MEL01C 2026-Q4、MEL01D 2027-Q2；本次僅親見 MEL01C「Year Built 2026」）。STACK 未公布 | Z10: 可租 | AA10: STACK 批發/超大規模出租；MEL01 租戶未公布。MEL01A（2023-08）與 MEL01B（2025-11 竣工）各 36 MW 已營運，未見公開的剩餘容量證據，故不另列。 | AB10: 未公布 | AC10: Wyndham 規劃許可（編號未取得） | AD10: 中 | AE10: Hickory 專案頁稱 MEL01C&D 位於「Laverton」且為單一三層建築；STACK 稱位於 Truganina、為兩棟各 54 MW；Hickory 專案頁稱 C&D 為單一三層建築且位於 Laverton，STACK 官網為兩棟各 54 MW、位於 Truganina。 地址備註：DCM wiki 登記園區為 369-399 Palmers Road；Baxtel 與 DatacenterHawk 用 399 Palmers Road。 | AG10: https://www.stackinfra.com/locations/asia-pacific/melbourne/mel01/ https://www.stackinfra.com/about/news-press/press-releases/stack-infrastructure-secures-aud-1-3-billion-in-green-financing-to-accelerate-expansion-of-mel01-hyperscale-campus-in-melbourne/ https://www.hickory.com.au/project/mel01cd-2/ | AH10: https://www.datacenterdynamics.com/en/news/stack-tops-out-swiss-data-center-completes-construction-in-melbourne/ https://baxtel.com/data-center/stack-mel01c https://datacentremoratorium.net/index.php/Resources:STACK_MEL01_Campus | AI10: https://www.stackinfra.com/locations/asia-pacific/melbourne/mel01/ https://www.stackinfra.com/about/news-press/press-releases/stack-infrastructure-secures-aud-1-3-billion-in-green-financing-to-accelerate-expansion-of-mel01-hyperscale-campus-in-melbourne/ https://www.hickory.com.au/project/mel01cd-2/ https://www.datacenterdynamics.com/en/news/stack-tops-out-swiss-data-center-completes-construction-in-melbourne/ https://baxtel.com/data-center/stack-mel01c https://baxtel.com/data-center/stack-mel01b https://datacentremoratorium.net/index.php/Resources:STACK_MEL01_Campus | AJ10: 開啟地圖 | AK10: VIC-A、VIC-B
A11: TAS-001 | B11: 塔斯馬尼亞州 | C11: Firmus Project Southgate — Launceston (St Leonards) AI Factory 園區 | D11: Firmus Technologies（自營 AI 雲／AI factory 業者） | E11: Firmus Technologies（澳洲註冊；官方稱自行設計、建造、擁有並營運；規劃申請代理 Pitt&Sherry）；投資人含 NVIDIA、Ellerston Capital（W.Media 2025-09-26） | F11: 23 Killafaddy Road, St Leonards TAS 7250 | G11: St Leonards | H11: 7250 | I11: City of Launceston | J11: -41.441718 | K11: 147.17672 | L11: 來源提供 | M11: 84 | N11: 關鍵負載 | O11: 44 | P11: Firmus Southgate 官網（firmus.co/infrastructure/southgate，2026-10-03 讀取）寫 84 MW Critical IT Load、PUE 小於 1.10。Stage 1a 44 MW、Stage 1b 合計約 90 MW（Firmus 2025-07 發布；DCD 2025-09-02）；Stage 2 另有 300 MW 計畫但『須取得核准』，未見任何申請文件，故不列入本筆。Aurora Energy 與 Firmus 簽 3 年零售協議（2026-03-25）：自 2026-08 起爬升，2026-11 起最高 104 MW。DatacenterMap 標 400 MW 為聚合器數字，疑為塔州三站合計（Firmus 對國會稱三站合約容量約 444 MW），不採用。 | Q11: 施工中 | R11: 觀察名單 (出租性待確認) | S11: 出租性待確認：Firmus 自述『design, build, own and operate』（國會調查意見書 #120，2026-09），運算硬體為自有；對外銷售的是專屬 AI 運算容量（dedicated AI infrastructure capacity）與 GPU 雲（NVIDIA DGX Cloud Lepton，2025-06-12），未見出租機房空間（colocation／powered shell／wholesale）的公開要約。已公布的大客戶合約在墨爾本（Firmus 與 CDC Data Centres 合作，約 18,400 GB300）與東南亞（OpenAI、Meta），並非 Tasmania。對需要 ≥5 MW『可租機房容量』的台灣客戶，只能走與 Firmus 洽談專屬容量合約這條路，故標 uncertain，是否保留請 先前 決定。 | T11: 2026-09-08 | U11: (1) Firmus 官網 Tasmania Community Hub（2026-10-03 讀取）稱 Launceston 是『our anchor site — under construction now』；(2) Firmus 新聞稿 2026-03-02（firmus.co/newsroom，另見 ITWire 同日轉載）稱 Tasmania 綠地 AI Factory 園區施工中、預計 2026 年底完工；(3) ABC 2026-06-15 報導現場已有施工機具、預計『early next year』啟用；(4) 塔州政府 2026-09-08 提交國會的文件（Pulse Tasmania 2026-09-09 報導）將 St Leonards 列為 under construction；(5) Minister Felix Ellis 2026-08-31 函確認 St Leonards AI factory 已完成規劃核准程序（該函措辭仍稱 proposed to operate）；(6) Aurora 新聞稿 2026-03-25 稱供電自 2026-08 起爬升。未取得動工通知書、CEMP 等官方動工文件（塔州制度下無公開對應文件）。 | V11: 未知（2025-09 媒體稱『即將動工』；2026-03-02 公司稱已在施工） | W11: 公司：2026 年底（2026-03-02）；ABC 2026-06-15：2027 年初；Aurora 供電爬升 2026-08～2026-11（最高 104 MW） | X11: 2026 Q4 – 2027 Q2 | Y11: operator（Firmus 新聞稿 2026-03-02）／press（ABC 2026-06-15）／Aurora Energy 新聞稿 2026-03-25 | Z11: 待確認 | AA11: Firmus 自述『design, build, own and operate』（國會調查意見書 #120，2026-09），運算硬體為自有；對外銷售的是專屬 AI 運算容量（dedicated AI infrastructure capacity）與 GPU 雲（NVIDIA DGX Cloud Lepton，2025-06-12），未見出租機房空間（colocation／powered shell／wholesale）的公開要約。已公布的大客戶合約在墨爾本（Firmus 與 CDC Data Centres 合作，約 18,400 GB300）與東南亞（OpenAI、Meta），並非 Tasmania。對需要 ≥5 MW『可租機房容量』的台灣客戶，只能走與 Firmus 洽談專屬容量合約這條路，故標 uncertain，是否保留請 先前 決定。 | AB11: Tasmania 場址無公開客戶／租戶。Firmus 全公司客戶：未具名『先前ing global technology company』（墨爾本，2026-03-02）、OpenAI 與 Meta（東南亞場址，2026-09）、Fireworks AI（Firmus AI Cloud，2026-08）；NVIDIA 為投資人與夥伴。 | AC11: City of Launceston 規劃許可（特別議會會議 2025-09-01 背書，Pulse Tasmania／DCD 2025-09-02；W.Media 2025-09-26 另稱『7 月核准』）；DA 編號未取得 | AD11: 中 | AE11: (1) 容量：Stage 1a 44 MW／1b 合計約 90 MW（Firmus 2025；DCD 2025-09-02）vs 官網 84 MW critical IT vs Aurora 協議上限 104 MW vs 國會問答『100 MW』（tasgreensmps 頁）vs DatacenterMap 400 MW（聚合器，疑為三站合計）。(2) GPU 數：36,800 GB300（Firmus 2026-03-02）vs 36,000（W.Media 2025-09-26，兩階段合計）vs AFR 2026-06-08 標題『26,000 Nvidia chips』（僅見標題，未開啟全文）。(3) 投資額：Stage 1a A$2.1bn（2025）vs Aurora 新聞稿 A$5bn（2026-03-25）。(4) 完工時間：2026 年中（2025-09 說法）→2026 年底（2026-03）→2027 初（ABC 2026-06-15）。(5) 核准日：特別議會會議 2025-09-01（Pulse、DCD 2025-09-02）vs W.Media 2025-09-26 稱『7 月核准』。(6) Baxtel 清單頁把 Launceston Campus 標成 Operational 20 MW（聚合器，無佐證）；Oxford Economics 函稱 Launceston 是 Firmus『first operating Australian site』，應指 2019 年研發站。 地址備註：門牌取自 DatacenterMap／Baxtel 頁面與 Pulse Tasmania 報導；用地約 5 公頃。City of Launceston 的 DA 原件與地號未取得（該議會網站對自動抓取回 403），建議 先前 向議會規劃登記冊核對。另有 Firmus 自 2019 年起的 Launceston 研發小站（容量未公布，推定小於 5 MW，不列入）。 | AF11: https://parliament.tas.gov.au/__data/assets/pdf_file/0012/110730/2026-08-13-ProfRazay.pdf https://www.parliament.tas.gov.au/__data/assets/pdf_file/0012/110064/Aurora-Energy-Media-Release-Firmus-Technologies-25-March-2026_Redacted.pdf https://www.parliament.tas.gov.au/__data/assets/pdf_file/0010/112231/120.-Firmus-combined.pdf https://www.parliament.tas.gov.au/__data/assets/pdf_file/0012/112260/152.-Hydro-Tasmania-Submission.pdf | AG11: https://firmus.co/infrastructure/southgate https://firmus.co/ourcommitments/tasmaniancommunity https://firmus.co/newsroom/firmus-signs-multi-year-agreement-with-global-hyperscale-customer-at-project-southgate https://firmus.co/newsroom/tasmanian-world-first-ai-factory-zone-clears-path-for-firmus-project-southgate https://firmus.co/newsroom/firmus-technologies-expands-regional-ai-access-through-nvidia-dgx-cloud-lepton | AH11: https://www.abc.net.au/news/2026-06-15/firmus-ai-company-tasmania-biggest-power-user-three-sites/106783142 https://www.abc.net.au/news/2026-07-03/firmus-ai-data-centres-is-tasmania-ready/106869862 https://www.abc.net.au/news/2026-09-09/six-new-confidential-data-centre-proposals-tasmania-revealed/107131974 https://pulsetasmania.com.au/news/document-reveals-six-secret-ai-data-centre-proposals-for-tasmania/ https://pulsetasmania.com.au/news/launceston-council-approves-major-2-1-billion-ai-data-centre/ https://www.datacenterdynamics.com/en/news/firmus-gets-go-ahead-for-ai-data-center-project-in-launceston-tasmania/ https://w.media/firmus-wins-approval-to-build-2-1bn-ai-factory-in-launceston/ https://w.media/firmus-raises-aud-330-million-for-tasmania-ai-factory/ https://itwire.com/it-industry-news/deals/firmus-signs-multi-year-agreement-with-global-hyperscale-customer-202603020801.html https://tasgreensmps.org/parliament/questions/firmus-technologies-launceston-ai-data-centre/ https://www.datacentermap.com/australia/launceston/project-southgate/ https://baxtel.com/data-center/firmus-launceston-campus | AI11: https://parliament.tas.gov.au/__data/assets/pdf_file/0012/110730/2026-08-13-ProfRazay.pdf https://www.parliament.tas.gov.au/__data/assets/pdf_file/0012/110064/Aurora-Energy-Media-Release-Firmus-Technologies-25-March-2026_Redacted.pdf https://www.parliament.tas.gov.au/__data/assets/pdf_file/0010/112231/120.-Firmus-combined.pdf https://www.parliament.tas.gov.au/__data/assets/pdf_file/0012/112260/152.-Hydro-Tasmania-Submission.pdf https://firmus.co/infrastructure/southgate https://firmus.co/ourcommitments/tasmaniancommunity https://firmus.co/newsroom/firmus-signs-multi-year-agreement-with-global-hyperscale-customer-at-project-southgate https://firmus.co/newsroom/tasmanian-world-first-ai-factory-zone-clears-path-for-firmus-project-southgate https://firmus.co/newsroom/firmus-technologies-expands-regional-ai-access-through-nvidia-dgx-cloud-lepton https://www.abc.net.au/news/2026-06-15/firmus-ai-company-tasmania-biggest-power-user-three-sites/106783142 https://www.abc.net.au/news/2026-07-03/firmus-ai-data-centres-is-tasmania-ready/106869862 https://www.abc.net.au/news/2026-09-09/six-new-confidential-data-centre-proposals-tasmania-revealed/107131974 https://pulsetasmania.com.au/news/document-reveals-six-secret-ai-data-centre-proposals-for-tasmania/ https://pulsetasmania.com.au/news/launceston-council-approves-major-2-1-billion-ai-data-centre/ https://www.datacenterdynamics.com/en/news/firmus-gets-go-ahead-for-ai-data-center-project-in-launceston-tasmania/ https://w.media/firmus-wins-approval-to-build-2-1bn-ai-factory-in-launceston/ https://w.media/firmus-raises-aud-330-million-for-tasmania-ai-factory/ https://itwire.com/it-industry-news/deals/firmus-signs-multi-year-agreement-with-global-hyperscale-customer-202603020801.html https://tasgreensmps.org/parliament/questions/firmus-technologies-launceston-ai-data-centre/ https://www.datacentermap.com/australia/launceston/project-southgate/ https://baxtel.com/data-center/firmus-launceston-campus | AJ11: 開啟地圖 | AK11: TAS-A
A12: VIC-006 | B12: 維多利亞州 | C12: Vantage MEL1（Tullamarine） | D12: Vantage Data Centers（APAC 業務屬 DigitalBridge 的 Skyline JV，Aware Super 持少數股權） | E12: Vantage Data Centers | F12: 43-45 Tullamarine Park Road, Tullamarine VIC 3043 | G12: Tullamarine | H12: 3043 | I12: Brimbank City Council（DCM wiki 列；未查證，Tullamarine 亦涉 Hume） | J12: -37.70818 | K12: 144.8719 | L12: 門牌級 | M12: 64 | N12: 關鍵負載 | P12: Vantage 官網（已讀）：單一資料中心、7 英畝（3 ha）、64 MW critical IT、25,000 m²、場內 66 kV 變電站、Jemena 供電；Baxtel 的 48 MW／三棟為舊版文案。 | Q12: 施工中 | R12: 主清單 | T12: 2026-10 | U12: Brimbank 公開規劃登記冊（資料截至 2025-07-22，已讀）：P435/2021『Use and development of the land for a data centre and removal of easements』（1/7、2/7、5 Allied Dr 與 43-45 Tullamarine Park Rd）2021-10-29 核發；Pt 3 修訂『alter the height and layout of the data centre』2024-12-05 受理、2025-03-18 核發。Vantage 官網文案為將來式（will provide）；Baxtel 標 Under Construction、2026 年建成；DCM wiki 列 Operating。沒有具日期的施工事件，狀態待查。登記冊未具名 Vantage，營運商取自 DCM wiki 對這些地址的標註。 | V12: 未公布 | W12: 2026（Baxtel，聚合器） | X12: 2026 Q4 – 2027 Q2 | Y12: 聚合器 | Z12: 大概可租 | AA12: Vantage 為批發型，官網稱專為 AI 工作負載設計。 | AB12: 未公布 | AC12: Brimbank P435/2021（Pt 3 修訂 2025-03-18 核發） | AD12: 中 | AE12: 狀態：施工中（Baxtel）vs 營運中（DCM wiki）vs 官網將來式；MW 64（官網）vs 48（Baxtel）；MW：64（官網/RenewMap/DCM wiki）vs 48（Baxtel）；狀態：Under construction（Baxtel）vs Operating（DCM wiki）；棟數：1 棟（官網）vs 3 棟（Baxtel）。Vantage 官網 APAC 地點只列 Melbourne（MEL1），沒有 MEL-C。 地址備註：Baxtel 與 DCM wiki：43-45 Tullamarine Park Rd；wiki 另列 5 Allied Drive, Tullamarine。Vantage 官網稱距墨爾本機場約 6 公里、鄰 NEXTDC M2 與 AirTrunk MEL2。 | AF12: https://records.brimbank.vic.gov.au/ExternalLinkAPI/api/document/?docKey=UHZYRmNFYWVDaUN0clNmekJwVXhMUExwUGpQcFE0VVFXVnp1NkdSYlZpc0lsS2NCZlVOWUxOVXBncy9DSUhHZg2 | AG12: https://vantage-dc.com/data-centers/melbourne/ https://vantage-dc.com/data-center-locations/apac/melbourne-australia/ | AH12: https://baxtel.com/data-center/vantage-melbourne-mel1 https://datacentremoratorium.net/index.php/Resources:Vantage_MEL1 | AI12: https://vantage-dc.com/data-centers/melbourne/ https://records.brimbank.vic.gov.au/ExternalLinkAPI/api/document/?docKey=UHZYRmNFYWVDaUN0clNmekJwVXhMUExwUGpQcFE0VVFXVnp1NkdSYlZpc0lsS2NCZlVOWUxOVXBncy9DSUhHZg2 https://datacentremoratorium.net/index.php/Resources:Vantage_MEL1 https://vantage-dc.com/data-center-locations/apac/melbourne-australia/ https://baxtel.com/data-center/vantage-melbourne-mel1 https://datacentremoratorium.net/index.php/Resources:Data_Centres_in_Greater_Melbourne | AJ12: 開啟地圖 | AK12: VIC-B、VIC-A
A13: NSW-004 | B13: 新南威爾斯州 | C13: GreenSquare DC SYD1 — Stage 1（既有資料中心建築改造，Norwest） | D13: GreenSquare DC (GSDC) | E13: GreenSquare DC | F13: 3 Brookhollow Avenue, Norwest NSW 2153 | G13: Norwest | H13: 2153 | I13: The Hills Shire | J13: -33.732527 | K13: 150.96802 | L13: 來源提供 | M13: 15 | N13: 口徑不明 | O13: 15 | P13: 15 MW 引自 先前資料（Stage 1 15 MW），我方未能獨立驗證；W.Media 2026-09-21 僅稱 SYD1 為『100MW-plus campus』；範疇界定函說明現址原有 4 MW 資料中心（D93/318，1993 年核准）。 | Q13: 施工中 | R13: 主清單 | T13: 2026-09-21 | U13: W.Media 2026-09-21：Stage 1 為既有資料中心建築的 adaptive reuse，建築正升級以支援高密度運算；首批客戶 Sharon AI 預計部署約 8,200 片 NVIDIA Blackwell Ultra GPU，初始營運目標 2026 Q4。先前資料 另稱總承包商為 Erilyan。因屬既有建築改造，Planning Portal 無對應 SSD 開工文件。 | V13: 未知（改造工程進行中） | W13: 2026-Q4（初始營運，W.Media 2026-09-21） | X13: 2026 Q4 – 2027 Q2 | Y13: W.Media 2026-09-21 引述 GreenSquare | Z13: 可租 | AA13: GreenSquare 為批發型出租業者；但 Stage 1 首批容量已由 Sharon AI 長期合約錨定（合約容量未公開），剩餘可租量不明。 | AB13: Sharon AI（Nasdaq 上市、NVIDIA Cloud Partner；首階段錨定客戶，2026-09 簽約） | AC13: 既有建築改造（D93/318，1993 年核准）；未見 SSD。Stage 2 見 SSD-81928961 | AD13: 中 | AE13: 完工時間：先前資料稱 Q3 2026，W.Media 稱初始營運 2026 Q4。首批客戶已簽，對 5 MW 新租戶而言 Stage 1 剩餘量可能很小；是否已完工：先前資料 2026-Q3 完工，Baxtel 稱已營運，無營運商確認；總量：先前資料 110 MW、官網 100MW+ IT、SSD EIS 的第二期 IT 96 MW；先前資料「Stage 1 15 MW」——與規劃小組 EDC/Stage 1 敘述的 14.9 MW 一致。 地址備註：Lot 2021 DP 831173，約 51,867 m2；位於 Norwest Business Park，Norwest 地鐵站以東約 500 m。Stage 1 與 Stage 2（）同一地址。 | AF13: https://www.planningportal.nsw.gov.au/major-projects/projects/brookhollow-avenue-data-centre-expansion-norwest https://www.planningportal.nsw.gov.au/planning-panel/alterations-and-additions-existing-data-centre | AG13: https://www.greensquaredc.com/locations https://greensquaredc.com/locations/ | AH13: https://w.media/greensquare-signs-sharon-ai-as-first-customer-for-syd1-data-centre-campus/ https://baxtel.com/data-center/greensquaredc-sydney-syd1 | AI13: https://www.planningportal.nsw.gov.au/major-projects/projects/brookhollow-avenue-data-centre-expansion-norwest https://majorprojects.planningportal.nsw.gov.au/prweb/PRRestService/mp/01/getContent?AttachRef=PDA-81670721%2120250328T083256.004+GMT https://w.media/greensquare-signs-sharon-ai-as-first-customer-for-syd1-data-centre-campus/ https://www.planningportal.nsw.gov.au/planning-panel/alterations-and-additions-existing-data-centre https://www.greensquaredc.com/locations https://api.apps1.nsw.gov.au/eplanning/data/v0/OnlineDA https://greensquaredc.com/locations/ | AJ13: 開啟地圖 | AK13: NSW-C、NSW-A、NSW-B
A14: NSW-005 | B14: 新南威爾斯州 | C14: CDC Marsden Park Data Centre Campus（Hollinsworth Road） | D14: CDC Data Centres（Canberra Data Centres） | E14: CDC Data Centres Pty Ltd（SSD 申請人，核准通知書所載）；股東含 Infratil（CDC 官網新聞標題） | F14: 105 and 113 Hollinsworth Road, Marsden Park NSW 2765 | G14: Marsden Park | H14: 2765 | I14: Blacktown | J14: -33.722607 | K14: 150.83633 | L14: 來源提供 | M14: 504 | N14: 耗電量 | P14: 入口網站/核准文件口徑為耗電 504 MW，六棟四層樓、720 MVA 變電站（先前資料讀取）；CDC 2024-10-25 新聞稿稱 504 MW 為 ICT capacity（口徑不同，IT 負載可能較低）；CDC 官網 Marsden Park 頁寫五棟四層加一棟兩層。前置議會 DA-24-00542（2024-11-14 核准，CIV A$53.94m）僅為 5 MW 設施。Baxtel 另列 79 MW、Q2 2026，屬聚合站估計。 | Q14: 施工中 | R14: 主清單 | T14: 2026-07-27 | U14: 入口網站 SSD-70889211 後續文件（於 2026-10-03 逐筆列出並從檔案識別碼解出上傳日）：Letter for SSDA Works Commencement（檔名 260714，上傳 2026-07-22）、CEMP Approval Letter（2026-05-12）、Approval of Staging Request（2026-04-24）、Approval of Updated Staging Request（2026-06-12）、ESCP 核准（2026-07-27）。CDC 官網新聞（2024-10-25）已稱 minor earthworks underway。 | V14: 2024-10（CDC 稱輕微土方，新聞稿 2024-10-25）；SSD 工程開工函 2026-07-14；CDC 官網排程的 early/civil works 自 2025-11 起 | W14: 分期交付 2027-09 至 2029-12（staggered handover through 2029） | X14: 2027 下半年 | Y14: CDC 官網 Marsden Park 頁排程（未標日期，2026-10-03 讀取）：early/civil 2025-11 至 2027-06、structural 2026-07 至 2027-11、services/fit-out 2027-02 至 2028-11、commissioning/handover 2027-09 至 2029-12 | Z14: 大概可租 | AA14: CDC 為批發型主機代管；2025 年簽下 555 MW、30 年的美國客戶合約（CDC 官網新聞標題，是否落在本園區未證實），Marsden Park 容量可能大多已預訂，需向 CDC 確認未預訂部分。 | AB14: 未公布；CDC 與一家美國客戶簽有 555 MW 合約（與本園區關係未證實） | AC14: SSD-70889211（2025-11-27 核准）；前置 DA-24-00542 / PPSSCC-562（2024-11-14 核准） | AD14: 高 | AE14: MW 口徑不一：入口網站 504 MW 為耗電、CDC 新聞稿 504 MW 為 ICT capacity；Baxtel 79 MW 且 Q2 2026 啟用，與 CDC 官網的 2027-09 起分期交付不符，以 CDC 官網為準；Portal 標題「504 MW power consumption」vs 評估報告「720 MW 最大電力 / 504 MW IT」；先前資料採 504 MW power consumption——應改註為 IT load 地址備註：SSD-70889211 與前置議會 DA-24-00542（PPSSCC-562）皆列 105 與 113 Hollinsworth Road；專用變電站亦在 Hollinsworth Road（CDC 官網）。 | AF14: https://www.planningportal.nsw.gov.au/major-projects/projects/marsden-park-data-centre https://www.planningportal.nsw.gov.au/planning-panel/canberra-data-centre https://majorprojects.planningportal.nsw.gov.au/prweb/PRRestService/mp/01/getContent?AttachRef=SSD-70889211%2120251128T050853.709+GMT https://majorprojects.planningportal.nsw.gov.au/prweb/PRRestService/mp/01/getContent?AttachRef=SSD-70889211-PA-23%2120260722T061549.935+GMT https://majorprojects.planningportal.nsw.gov.au/prweb/PRRestService/mp/01/getContent?AttachRef=SSD-70889211-PA-21%2120260612T050533.584+GMT | AG14: https://www.cdc.com.au/locations/sydney-and-regional-nsw/marsden-park/ https://www.cdc.com.au/resources/news/cdc-data-centres-breaks-ground-on-new-state-of-the-art-data-centre-development-in-marsden-park-industrial-precinct/ | AH14: https://baxtel.com/data-center/cdc-marsden-park-campus | AI14: https://www.planningportal.nsw.gov.au/major-projects/projects/marsden-park-data-centre https://www.planningportal.nsw.gov.au/planning-panel/canberra-data-centre https://www.cdc.com.au/locations/sydney-and-regional-nsw/marsden-park/ https://www.cdc.com.au/resources/news/cdc-data-centres-breaks-ground-on-new-state-of-the-art-data-centre-development-in-marsden-park-industrial-precinct/ https://baxtel.com/data-center/sydney https://majorprojects.planningportal.nsw.gov.au/prweb/PRRestService/mp/01/getContent?AttachRef=SSD-70889211%2120251128T050853.709+GMT https://majorprojects.planningportal.nsw.gov.au/prweb/PRRestService/mp/01/getContent?AttachRef=SSD-70889211-PA-23%2120260722T061549.935+GMT https://majorprojects.planningportal.nsw.gov.au/prweb/PRRestService/mp/01/getContent?AttachRef=SSD-70889211-PA-21%2120260612T050533.584+GMT | AJ14: 開啟地圖 | AK14: NSW-A、NSW-B
